<?xml version="1.0" ?>
<!-- =================================================================================== -->
<!-- |    This document was autogenerated by xacro from /root/crs_ws_fanuc/install/crs_support/share/crs_support/urdf/crs.urdf.xacro | -->
<!-- |    EDITING THIS FILE BY HAND IS NOT RECOMMENDED                                 | -->
<!-- =================================================================================== -->
<robot name="crs">
  <link name="preview/base_link">
    <visual>
      <origin rpy="0 0 3.14159265359" xyz="0 0 0"/>
      <geometry>
        <mesh filename="package://crs_support/meshes/ur10e/visual/base.dae"/>
      </geometry>
      <material name="LightGrey">
        <color rgba="0.7 0.7 0.7 1.0"/>
      </material>
    </visual>
    <collision>
      <origin rpy="0 0 3.14159265359" xyz="0 0 0"/>
      <geometry>
        <mesh filename="package://crs_support/meshes/ur10e/collision/base.stl"/>
      </geometry>
    </collision>
    <inertial>
      <mass value="4.0"/>
      <origin rpy="0 0 0" xyz="0.0 0.0 0.0"/>
      <inertia ixx="0.0061063308908" ixy="0.0" ixz="0.0" iyy="0.0061063308908" iyz="0.0" izz="0.01125"/>
    </inertial>
  </link>
  <joint name="preview/shoulder_pan_joint" type="revolute">
    <parent link="preview/base_link"/>
    <child link="preview/shoulder_link"/>
    <origin rpy="0 0 3.14159249728" xyz="0 0 0.180920744391"/>
    <axis xyz="0 0 1"/>
    <limit effort="330.0" lower="-4" upper="3.28" velocity="3.14"/>
    <dynamics damping="0.0" friction="0.0"/>
  </joint>
  <link name="preview/shoulder_link">
    <visual>
      <origin rpy="0 0 3.14159265359" xyz="0 0 0"/>
      <geometry>
        <mesh filename="package://crs_support/meshes/ur10e/visual/shoulder.dae"/>
      </geometry>
      <material name="LightGrey">
        <color rgba="0.7 0.7 0.7 1.0"/>
      </material>
    </visual>
    <collision>
      <origin rpy="0 0 3.14159265359" xyz="0 0 0"/>
      <geometry>
        <mesh filename="package://crs_support/meshes/ur10e/collision/shoulder.stl"/>
      </geometry>
    </collision>
    <inertial>
      <mass value="7.778"/>
      <origin rpy="0 0 0" xyz="0.0 0.0 0.0"/>
      <inertia ixx="0.0314743125769" ixy="0.0" ixz="0.0" iyy="0.0314743125769" iyz="0.0" izz="0.021875625"/>
    </inertial>
  </link>
  <joint name="preview/shoulder_lift_joint" type="revolute">
    <parent link="preview/shoulder_link"/>
    <child link="preview/upper_arm_link"/>
    <origin rpy="1.57065145242 0 -2.70337965131e-06" xyz="0.00013292041689 0 0"/>
    <axis xyz="0 0 1"/>
    <limit effort="330.0" lower="-6.28318530718" upper="6.28318530718" velocity="3.14"/>
    <dynamics damping="0.0" friction="0.0"/>
  </joint>
  <link name="preview/upper_arm_link">
    <visual>
      <origin rpy="1.57079632679 0 -1.57079632679" xyz="0 0 0.1762"/>
      <geometry>
        <mesh filename="package://crs_support/meshes/ur10e/visual/upperarm.dae"/>
      </geometry>
      <material name="LightGrey">
        <color rgba="0.7 0.7 0.7 1.0"/>
      </material>
    </visual>
    <collision>
      <origin rpy="1.57079632679 0 -1.57079632679" xyz="0 0 0.1762"/>
      <geometry>
        <mesh filename="package://crs_support/meshes/ur10e/collision/upper_arm_multibody.dae"/>
      </geometry>
    </collision>
    <inertial>
      <mass value="12.93"/>
      <origin rpy="0 1.57079632679 0" xyz="-0.3059856723 0.0 0.175"/>
      <inertia ixx="0.421716012238" ixy="0.0" ixz="0.0" iyy="0.421716012238" iyz="0.0" izz="0.036365625"/>
    </inertial>
  </link>
  <joint name="preview/elbow_joint" type="revolute">
    <parent link="preview/upper_arm_link"/>
    <child link="preview/forearm_link"/>
    <origin rpy="3.14047492209 3.14117521433 3.14159104748" xyz="-0.611971344601 0 0"/>
    <axis xyz="0 0 1"/>
    <limit effort="150.0" lower="-6.28318530718" upper="6.28318530718" velocity="3.14"/>
    <dynamics damping="0.0" friction="0.0"/>
  </joint>
  <link name="preview/forearm_link">
    <visual>
      <origin rpy="1.57079632679 0 -1.57079632679" xyz="0 0 0.0393"/>
      <geometry>
        <mesh filename="package://crs_support/meshes/ur10e/visual/forearm.dae"/>
      </geometry>
      <material name="LightGrey">
        <color rgba="0.7 0.7 0.7 1.0"/>
      </material>
    </visual>
    <collision>
      <origin rpy="1.57079632679 0 -1.57079632679" xyz="0 0 0.0393"/>
      <geometry>
        <mesh filename="package://crs_support/meshes/ur10e/collision/forearm_multibody.dae"/>
      </geometry>
    </collision>
    <inertial>
      <mass value="3.87"/>
      <origin rpy="0 1.57079632679 0" xyz="-0.3059856723 0.0 0.0393"/>
      <inertia ixx="0.110614284666" ixy="0.0" ixz="0.0" iyy="0.110614284666" iyz="0.0" izz="0.010884375"/>
    </inertial>
  </link>
  <joint name="preview/wrist_1_joint" type="revolute">
    <parent link="preview/forearm_link"/>
    <child link="preview/wrist_1_link"/>
    <origin rpy="3.13872123266 -3.14053617519 3.14158723656" xyz="-0.571064941288 0.000500820247035 0.174414995927"/>
    <axis xyz="0 0 1"/>
    <limit effort="54.0" lower="-6.28318530718" upper="6.28318530718" velocity="6.28"/>
    <dynamics damping="0.0" friction="0.0"/>
  </joint>
  <link name="preview/wrist_1_link">
    <visual>
      <origin rpy="1.57079632679 0 0" xyz="0 0 -0.135"/>
      <geometry>
        <mesh filename="package://crs_support/meshes/ur10e/visual/wrist1.dae"/>
      </geometry>
      <material name="LightGrey">
        <color rgba="0.7 0.7 0.7 1.0"/>
      </material>
    </visual>
    <collision>
      <origin rpy="1.57079632679 0 0" xyz="0 0 -0.135"/>
      <geometry>
        <mesh filename="package://crs_support/meshes/ur10e/collision/wrist1.stl"/>
      </geometry>
    </collision>
    <inertial>
      <mass value="1.96"/>
      <origin rpy="0 0 0" xyz="0.0 0.0 0.0"/>
      <inertia ixx="0.00510211926321" ixy="0.0" ixz="0.0" iyy="0.00510211926321" iyz="0.0" izz="0.0055125"/>
    </inertial>
  </link>
  <joint name="preview/wrist_2_joint" type="revolute">
    <parent link="preview/wrist_1_link"/>
    <child link="preview/wrist_2_link"/>
    <origin rpy="1.57117550062 0 -9.13444434245e-07" xyz="5.96404309737e-05 -0.119843553735 -4.54415414531e-05"/>
    <axis xyz="0 0 1"/>
    <limit effort="54.0" lower="-6.28318530718" upper="6.28318530718" velocity="6.28"/>
    <dynamics damping="0.0" friction="0.0"/>
  </joint>
  <link name="preview/wrist_2_link">
    <visual>
      <origin rpy="0 0 0" xyz="0 0 -0.12"/>
      <geometry>
        <mesh filename="package://crs_support/meshes/ur10e/visual/wrist2.dae"/>
      </geometry>
      <material name="LightGrey">
        <color rgba="0.7 0.7 0.7 1.0"/>
      </material>
    </visual>
    <collision>
      <origin rpy="0 0 0" xyz="0 0 -0.12"/>
      <geometry>
        <mesh filename="package://crs_support/meshes/ur10e/collision/wrist2.stl"/>
      </geometry>
    </collision>
    <inertial>
      <mass value="1.96"/>
      <origin rpy="0 0 0" xyz="0.0 0.0 0.0"/>
      <inertia ixx="0.00493642595291" ixy="0.0" ixz="0.0" iyy="0.00493642595291" iyz="0.0" izz="0.0055125"/>
    </inertial>
  </link>
  <joint name="preview/wrist_3_joint" type="revolute">
    <parent link="preview/wrist_2_link"/>
    <child link="preview/wrist_3_link"/>
    <origin rpy="1.57170379674 3.14159265359 3.14159254819" xyz="1.57784168351e-05 0.115533666641 0.000104843358957"/>
    <axis xyz="0 0 1"/>
    <limit effort="54.0" lower="-6.28318530718" upper="6.28318530718" velocity="6.28"/>
    <dynamics damping="0.0" friction="0.0"/>
  </joint>
  <link name="preview/wrist_3_link">
    <visual>
      <origin rpy="1.57079632679 0 0" xyz="0 0 -0.1168"/>
      <geometry>
        <mesh filename="package://crs_support/meshes/ur10e/visual/wrist3.dae"/>
      </geometry>
      <material name="LightGrey">
        <color rgba="0.7 0.7 0.7 1.0"/>
      </material>
    </visual>
    <collision>
      <origin rpy="1.57079632679 0 0" xyz="0 0 -0.1168"/>
      <geometry>
        <mesh filename="package://crs_support/meshes/ur10e/collision/wrist3.stl"/>
      </geometry>
    </collision>
    <inertial>
      <mass value="0.202"/>
      <origin rpy="0 0 0" xyz="0.0 0.0 -0.025"/>
      <inertia ixx="0.000144345775595" ixy="0.0" ixz="0.0" iyy="0.000144345775595" iyz="0.0" izz="0.000204525"/>
    </inertial>
  </link>
  <joint name="preview/ee_fixed_joint" type="fixed">
    <parent link="preview/wrist_3_link"/>
    <child link="preview/ee_link"/>
    <origin rpy="0.0 -1.57079632679 1.57079632679" xyz="0.0 0.0 0.0"/>
  </joint>
  <link name="preview/ee_link">
    <collision>
      <geometry>
        <box size="0.01 0.01 0.01"/>
      </geometry>
      <origin rpy="0 0 0" xyz="-0.01 0 0"/>
    </collision>
    <inertial>
      <mass value="0.1"/>
      <inertia ixx="0.03" ixy="0.0" ixz="0.0" iyy="0.03" iyz="0.0" izz="0.03"/>
    </inertial>
  </link>
  <link name="preview/base"/>
  <joint name="preview/base_link-base_fixed_joint" type="fixed">
    <origin rpy="0 0 3.14" xyz="0 0 0"/>
    --&gt;
        
    <parent link="preview/base"/>
    <child link="preview/base_link"/>
  </joint>
  <link name="preview/tool0"/>
  <joint name="preview/wrist_3_link-tool0_fixed_joint" type="fixed">
    <origin rpy="0 0 0" xyz="0 0 0"/>
    <parent link="preview/wrist_3_link"/>
    <child link="preview/tool0"/>
  </joint>
  <link name="preview/eoat_link">
    <visual>
      <geometry>
        <mesh filename="package://crs_support/meshes/end_effector/visual/tool.stl"/>
      </geometry>
      <material name="Orange">
        <color rgba="1.0 0.4 0.0 1.0"/>
      </material>
    </visual>
    <visual>
      <geometry>
        <mesh filename="package://crs_support/meshes/end_effector/visual/sander.stl"/>
      </geometry>
      <material name="Orange">
        <color rgba="1.0 0.4 0.0 1.0"/>
      </material>
    </visual>
    <collision>
      <geometry>
        <mesh filename="package://crs_support/meshes/end_effector/collision/tool_collision.stl"/>
      </geometry>
    </collision>
    <collision>
      <geometry>
        <mesh filename="package://crs_support/meshes/end_effector/collision/sander_collision.stl"/>
      </geometry>
    </collision>
    <visual>
      <geometry>
        <cylinder length="0.05" radius="0.0125"/>
      </geometry>
      <origin rpy="0 1.57 0" xyz="0.11 -0.055 0.055"/>
    </visual>
    <collision>
      <geometry>
        <cylinder length="0.05" radius="0.0125"/>
      </geometry>
      <origin rpy="0 1.57 0" xyz="0.11 -0.055 0.055"/>
    </collision>
    <inertial>
      <mass value="0.01"/>
      <origin rpy="0 0 0" xyz="0.0 0.0 0.0"/>
      <inertia ixx="0.000526462289415" ixy="0.0" ixz="0.0" iyy="0.000526462289415" iyz="0.0" izz="0.000568125"/>
    </inertial>
  </link>
  <joint name="preview/tool0_to_eoat_link" type="fixed">
    <parent link="preview/tool0"/>
    <child link="preview/eoat_link"/>
    <origin rpy="0.0 0.0 0" xyz="0.00 0.00 0.00"/>
  </joint>
  <link name="preview/robot_stand">
    <visual>
      <origin rpy="1.57079632679 0 0" xyz="0 0 -0.1168"/>
      <geometry>
        <mesh filename="package://crs_support/meshes/Mockup/visual/Mockup3_6_Frame_noTools_small.stl"/>
      </geometry>
      <material name="LightGrey">
        <color rgba="0.7 0.7 0.7 1.0"/>
      </material>
    </visual>
    <visual>
      <origin rpy="1.57079632679 0 0" xyz="0.20 0.2 -0.1168"/>
      <geometry>
        <mesh filename="package://crs_support/meshes/Mockup/visual/mockup_cart_v4.stl"/>
      </geometry>
      <material name="LightGrey">
        <color rgba="0.7 0.7 0.7 1.0"/>
      </material>
    </visual>
    <collision>
      <origin rpy="1.57079632679 0 0" xyz="0.20 0.2 -0.1168"/>
      <geometry>
        <mesh filename="package://crs_support/meshes/Mockup/collision/Mockup3_6_Cart_collision.stl"/>
      </geometry>
    </collision>
    <collision>
      <!-- Right Wall-->
      <geometry>
        <box size="3.0 2.14 0.1"/>
      </geometry>
      <origin rpy="0 0 0" xyz="-0.5 -1.1 1.38"/>
    </collision>
    <collision>
      <!-- Left Wall-->
      <geometry>
        <box size="3.0 2.14 0.1"/>
      </geometry>
      <origin rpy="0 0 0" xyz="-0.5 -1.1 -1.33"/>
    </collision>
    <collision>
       Front Wall
            
      <geometry>
        <box size="0.1 2.14 3.0"/>
      </geometry>
      <origin rpy="0 0 0" xyz="0.85 -1.1 0.0"/>
    </collision>
    <collision>
       Back Wall bottom Half
            
      <geometry>
        <box size="0.4 1.1 3.0"/>
      </geometry>
      <origin rpy="0 0 0" xyz="-2.06 -0.6 0.0"/>
    </collision>
    <collision>
       Back Wall top beam
            
      <geometry>
        <box size="1.25 0.12 3.0"/>
      </geometry>
      <origin rpy="0 0 0" xyz="0.38 -2.135 0.0"/>
    </collision>
    <collision>
       Back Wall Half right
            
      <geometry>
        <box size="0.1 0.3 0.7"/>
      </geometry>
      <origin rpy="-0.786 0 0" xyz="-2.06 -1.9 1.15"/>
    </collision>
    <collision>
       Back Wall Half left
            
      <geometry>
        <box size="0.1 0.3 0.7"/>
      </geometry>
      <origin rpy="0.786 0 0" xyz="-2.06 -1.9 -1.15"/>
    </collision>
    <collision>
      <!-- Top back beam-->
      <geometry>
        <box size="0.34 0.15 3.0"/>
      </geometry>
      <origin rpy="0 0 0" xyz="-1.0 -2.135 0.0"/>
    </collision>
    <collision>
      <!-- Corner Bracket 1-->
      <geometry>
        <box size="1.25 0.12 1.25"/>
      </geometry>
      <origin rpy="0 0.785 0" xyz="-2.06 -2.135 -1.33"/>
    </collision>
    <collision>
      <!-- Corner Bracket 2-->
      <geometry>
        <box size="1.25 0.12 1.25"/>
      </geometry>
      <origin rpy="0 0.785 0" xyz="-2.06 -2.135 1.38"/>
    </collision>
    <!--<collision>  fake floor
            <geometry>
                <box size="3.0 0.12 2.5" />
            </geometry>
            <origin rpy="0 0 0" xyz="-0.65 -0.82 0" />
        </collision>-->
    <inertial>
      <mass value="0.1"/>
      <inertia ixx="0.03" ixy="0.0" ixz="0.0" iyy="0.03" iyz="0.0" izz="0.03"/>
    </inertial>
  </link>
  <joint name="preview/robot_base_joint" type="fixed">
    <parent link="preview/robot_stand"/>
    <child link="preview/base"/>
    <origin rpy="-1.570796 -1.570796 0.0" xyz="-1.030659 -2.037406 0.7977 "/>
    <axis xyz="1 0 0"/>
    <limit effort="1.0" lower="-0.1" upper="1.9" velocity=".01"/>
  </joint>
  <link name="world"/>
  <joint name="preview/robot_stand_joint" type="fixed">
    <parent link="world"/>
    <child link="preview/robot_stand"/>
    <origin rpy="-1.571 0 0" xyz="0 0 0"/>
  </joint>
  <link name="preview/gazebo_camera_link"/>
  <joint name="preview/gazebo_camera_joint" type="fixed">
    <origin rpy="1.57 -1.57 0.0" xyz="0.0 0.0 0.0"/>
    <parent link="preview/camera_link_optical"/>
    <child link="preview/gazebo_camera_link"/>
  </joint>
  <link name="preview/camera_link_optical"/>
  <joint name="preview/camera_optical_joint" type="fixed">
    <origin rpy="-0.7854 0 0" xyz="-0.021 0.0797 0.06525"/>
    <parent link="preview/eoat_link"/>
    <child link="preview/camera_link_optical"/>
  </joint>
  <link name="preview/camera_link"/>
  <joint name="preview/camera_link_joint" type="fixed">
    <origin rpy="1.57 -1.57 0" xyz="0.0 0.0 0.0"/>
    <parent link="preview/camera_link_optical"/>
    <child link="preview/camera_link"/>
  </joint>
  <link name="preview/sander_center_link"/>
  <link name="preview/sander_intermediate_link">
    <visual>
      <geometry>
        <cylinder length="0.06" radius="0.06425"/>
      </geometry>
      <origin rpy="0 0 0" xyz="0 0 0"/>
    </visual>
    <collision>
      <geometry>
        <cylinder length="0.025" radius="0.06425"/>
      </geometry>
      <origin rpy="0 0 0" xyz="0 0 0"/>
    </collision>
    <visual>
      <geometry>
        <cylinder length="0.20" radius="0.0125"/>
      </geometry>
      <origin rpy="1.57 0 0" xyz="-0.0175 -0.1 -.0375"/>
    </visual>
    <visual>
      <geometry>
        <cylinder length="0.0254" radius="0.0125"/>
      </geometry>
      <origin rpy="0 1.57 0" xyz="0.0 -0.2 -.0375"/>
    </visual>
    <collision>
      <geometry>
        <cylinder length="0.20" radius="0.0125"/>
      </geometry>
      <origin rpy="1.57 0 0" xyz="-0.0175 -0.1 -.0375"/>
    </collision>
    <collision>
      <geometry>
        <cylinder length="0.0254" radius="0.0125"/>
      </geometry>
      <origin rpy="0 1.57 0" xyz="0.0 -0.2 -.0375"/>
    </collision>
  </link>
  <joint name="preview/sander_intermediate_to_sander_center_link" type="fixed">
    <parent link="preview/sander_intermediate_link"/>
    <child link="preview/sander_center_link"/>
    <origin rpy="0.0 0.0 0.0" xyz="0.0 0.0 0.03"/>
  </joint>
  <joint name="preview/tool0_to_sander_intermediate_link" type="fixed">
    <parent link="preview/eoat_link"/>
    <child link="preview/sander_intermediate_link"/>
    <origin rpy="0.7854 0.0 0.0" xyz="0.0 -0.17503 0.15497"/>
  </joint>
  <transmission name="trans_shoulder_pan_joint">
    <type>transmission_interface/SimpleTransmission</type>
    <joint name="preview/shoulder_pan_joint">
      <hardwareInterface>hardware_interface/EffortJointInterface</hardwareInterface>
    </joint>
    <actuator name="shoulder_pan_joint_motor">
      <hardwareInterface>hardware_interface/EffortJointInterface</hardwareInterface>
      <mechanicalReduction>1</mechanicalReduction>
    </actuator>
  </transmission>
  <transmission name="trans_shoulder_lift_joint">
    <type>transmission_interface/SimpleTransmission</type>
    <joint name="preview/shoulder_lift_joint">
      <hardwareInterface>hardware_interface/EffortJointInterface</hardwareInterface>
    </joint>
    <actuator name="shoulder_lift_joint_motor">
      <hardwareInterface>hardware_interface/EffortJointInterface</hardwareInterface>
      <mechanicalReduction>1</mechanicalReduction>
    </actuator>
  </transmission>
  <transmission name="trans_elbow_joint">
    <type>transmission_interface/SimpleTransmission</type>
    <joint name="preview/elbow_joint">
      <hardwareInterface>hardware_interface/EffortJointInterface</hardwareInterface>
    </joint>
    <actuator name="elbow_joint_motor">
      <hardwareInterface>hardware_interface/EffortJointInterface</hardwareInterface>
      <mechanicalReduction>1</mechanicalReduction>
    </actuator>
  </transmission>
  <transmission name="trans_wrist_1_joint">
    <type>transmission_interface/SimpleTransmission</type>
    <joint name="preview/wrist_1_joint">
      <hardwareInterface>hardware_interface/EffortJointInterface</hardwareInterface>
    </joint>
    <actuator name="wrist_1_joint_motor">
      <hardwareInterface>hardware_interface/EffortJointInterface</hardwareInterface>
      <mechanicalReduction>1</mechanicalReduction>
    </actuator>
  </transmission>
  <transmission name="trans_wrist_2_joint">
    <type>transmission_interface/SimpleTransmission</type>
    <joint name="preview/wrist_2_joint">
      <hardwareInterface>hardware_interface/EffortJointInterface</hardwareInterface>
    </joint>
    <actuator name="wrist_2_joint_motor">
      <hardwareInterface>hardware_interface/EffortJointInterface</hardwareInterface>
      <mechanicalReduction>1</mechanicalReduction>
    </actuator>
  </transmission>
  <transmission name="trans_wrist_3_joint">
    <type>transmission_interface/SimpleTransmission</type>
    <joint name="preview/wrist_3_joint">
      <hardwareInterface>hardware_interface/EffortJointInterface</hardwareInterface>
    </joint>
    <actuator name="wrist_3_joint_motor">
      <hardwareInterface>hardware_interface/EffortJointInterface</hardwareInterface>
      <mechanicalReduction>1</mechanicalReduction>
    </actuator>
  </transmission>
  <transmission name="trans_robot_base_joint">
    <type>transmission_interface/SimpleTransmission</type>
    <joint name="preview/robot_base_joint">
      <hardwareInterface>hardware_interface/EffortJointInterface</hardwareInterface>
    </joint>
    <actuator name="robot_base_joint_motor">
      <hardwareInterface>hardware_interface/EffortJointInterface</hardwareInterface>
      <mechanicalReduction>1</mechanicalReduction>
    </actuator>
  </transmission>
  <gazebo reference="preview/robot_stand">
    <selfCollide>true</selfCollide>
  </gazebo>
  <gazebo reference="preview/base_link">
    <selfCollide>true</selfCollide>
  </gazebo>
  <gazebo reference="preview/shoulder_link">
    <selfCollide>true</selfCollide>
  </gazebo>
  <gazebo reference="preview/upper_arm_link">
    <selfCollide>true</selfCollide>
  </gazebo>
  <gazebo reference="preview/wrist_1_joint">
    <selfCollide>true</selfCollide>
  </gazebo>
  <gazebo reference="preview/forearm_link">
    <selfCollide>true</selfCollide>
  </gazebo>
  <gazebo reference="preview/wrist_2_joint">
    <selfCollide>true</selfCollide>
  </gazebo>
  <gazebo reference="preview/wrist_3_joint">
    <selfCollide>true</selfCollide>
  </gazebo>
  <gazebo reference="preview/ee_link">
    <selfCollide>true</selfCollide>
  </gazebo>
  <gazebo reference="preview/eoat_link">
    <selfCollide>true</selfCollide>
  </gazebo>
  <gazebo reference="preview/tool0">
    <selfCollide>true</selfCollide>
  </gazebo>
  <gazebo reference="preview/gazebo_camera_link">
    <sensor name="sensor_name" type="depth">
      <!-- Set always_on only sensor, not on plugin -->
      <always_on>1</always_on>
      <!-- Set update_rate only sensor, not on plugin -->
      <update_rate>5</update_rate>
      <camera name="camera_name">
        <image>
          <width>320</width>
          <height>200</height>
        </image>
        <distortion>
          <k1>-0.0</k1>
          <k2>0.0</k2>
          <k3>0.0</k3>
          <p1>-0.0</p1>
          <p2>-0.0</p2>
          <center>0.5 0.5</center>
        </distortion>
      </camera>
      <plugin filename="libgazebo_ros_camera.so" name="plugin_name">
        <!-- Change namespace, camera name and topics so:
                 * Raw images are published to: /custom_ns/custom_camera/custom_image
                 * Depth images are published to: /custom_ns/custom_camera/custom_image_depth
                 * Raw image camera info is published to: /custom_ns/custom_camera/custom_info_raw
                 * Depth image camera info is published to: /custom_ns/custom_camera/custom_info_depth
                 * Point cloud is published to: /custom_ns/custom_camera/custom_points
            -->
        <ros>
          <namespace>custom_ns</namespace>
          <argument>camera/image_raw:=camera/custom_image</argument>
          <argument>camera/image_depth:=camera/custom_image_depth</argument>
          <argument>camera/camera_info:=camera/custom_info_raw</argument>
          <argument>camera/camera_info_depth:=camera/custom_info_depth</argument>
          <argument>camera/points:=camera/pointcloud</argument>
        </ros>
        <!-- Set camera name. If empty, defaults to sensor name (i.e. "sensor_name") -->
        <camera_name>camera</camera_name>
        <frame_name>camera_link_optical</frame_name>
        <!-- Set TF frame name. If empty, defaults to link name (i.e. "link_name") -->
        <hack_baseline>0.07</hack_baseline>
        <!-- No need to repeat distortion parameters or to set autoDistortion -->
        <min_depth>0.1</min_depth>
      </plugin>
    </sensor>
  </gazebo>
  <gazebo>
    <plugin filename="libgazebo_ros_joint_state_publisher.so" name="gazebo_ros_joint_state_publisher">
      <ros>
        <namespace>/test</namespace>
        <argument>joint_states:=joint_states</argument>
      </ros>
      <update_rate>50</update_rate>
      <joint_name>preview/shoulder_pan_joint</joint_name>
      <joint_name>preview/shoulder_lift_joint</joint_name>
      <joint_name>preview/elbow_joint</joint_name>
      <joint_name>preview/wrist_1_joint</joint_name>
      <joint_name>preview/wrist_2_joint</joint_name>
      <joint_name>preview/wrist_3_joint</joint_name>
    </plugin>
    <plugin filename="libcrs_gazebo_plugins_joint_pose_trajectory.so" name="crs_gazebo_plugins_joint_pose_trajectory">
      <ros>
        <namespace>sim</namespace>
        <argument>follow_joint_trajectory:=preview/follow_joint_trajectory</argument>
      </ros>
      <update_rate>20</update_rate>
    </plugin>
  </gazebo>
</robot>
