<?xml version="1.0"?>
<robot xmlns:xacro="http://wiki.ros.org/xacro">
  <xacro:include filename="$(find fanuc_resources)/urdf/common_materials.xacro"/>

  <xacro:macro name="fanuc_r2000ic165f" params="prefix">
    <!-- links: main serial chain -->
    <link name="world" />
    <joint name="${prefix}world_base_link" type="fixed">
        <parent link="world" />
        <child link="${prefix}base_link" />
        <origin rpy="0 0 0" xyz="-2.5 0 0" />
    </joint>

    <link name="${prefix}base_link">
      <visual>
        <origin xyz="0 0 0" rpy="0 0 0"/>
        <geometry>
          <mesh filename="package://fanuc_r2000ic_support/meshes/r2000ic165f/visual/base_link.stl"/>
        </geometry>
        <xacro:material_fanuc_gray40 />
      </visual>
      <collision>
        <origin xyz="0 0 0" rpy="0 0 0"/>
        <geometry>
          <mesh filename="package://fanuc_r2000ic_support/meshes/r2000ic165f/collision/base_link.stl"/>
        </geometry>
      </collision>

      <inertial>
               <mass value="10.0" />
               <origin rpy="0 0 0" xyz="0.0 0.0 0.0" />
               <inertia ixx="0.002695" ixy="0.000023" ixz="0.000157" iyy="0.004043" iyz="0.000023" izz="0.006096" />
      </inertial>


    </link>
    <link name="${prefix}link_1">
      <visual>
        <origin xyz="0 0 0" rpy="0 0 0"/>
        <geometry>
          <mesh filename="package://fanuc_r2000ic_support/meshes/r2000ic165f/visual/link_1.stl"/>
        </geometry>
        <xacro:material_fanuc_yellow />
      </visual>
      <collision>
        <origin xyz="0 0 0" rpy="0 0 0"/>
        <geometry>
          <mesh filename="package://fanuc_r2000ic_support/meshes/r2000ic165f/collision/link_1.stl"/>
        </geometry>
      </collision>
      <inertial>
                <mass value="5.0" />
                <origin rpy="0 0 0" xyz="0.010863 0.053239 0.523328" />
                <inertia ixx="0.012932" ixy="0.003309" ixz=" -0.000331" iyy="0.018366" iyz="-0.000071" izz="0.019767" />
      </inertial>
    </link>
    <link name="${prefix}link_2">
      <visual>
        <origin xyz="0 0 0" rpy="0 0 0"/>
        <geometry>
          <mesh filename="package://fanuc_r2000ic_support/meshes/r2000ic165f/visual/link_2.stl"/>
        </geometry>
        <xacro:material_fanuc_yellow />
      </visual>
      <collision>
        <origin xyz="0 0 0" rpy="0 0 0"/>
        <geometry>
          <mesh filename="package://fanuc_r2000ic_support/meshes/r2000ic165f/collision/link_2.stl"/>
        </geometry>
      </collision>
      <inertial>
                <mass value="4.0" />
                <origin rpy="0 0 0" xyz="-0.001481 0.204359 0.436864" />
                <inertia ixx="0.014390" ixy="0.000091" ixz="-0.000323" iyy="0.015120" iyz="-0.001213" izz="0.002053" />
      </inertial>
    </link>
    <link name="${prefix}link_3">
      <visual>
        <origin xyz="0 0 0" rpy="0 0 0"/>
        <geometry>
          <mesh filename="package://fanuc_r2000ic_support/meshes/r2000ic165f/visual/link_3.stl"/>
        </geometry>
        <xacro:material_fanuc_yellow />
      </visual>
      <collision>
        <origin xyz="0 0 0" rpy="0 0 0"/>
        <geometry>
          <mesh filename="package://fanuc_r2000ic_support/meshes/r2000ic165f/collision/link_3.stl"/>
        </geometry>
      </collision>
      <inertial>
               <mass value="4.0" />
               <origin rpy="0 0 0" xyz="0.059293 0.012994 0.109078" />
               <inertia ixx="0.001451" ixy="0.000017" ixz="-0.000177" iyy="0.001441" iyz="0.000072" izz="0.001041" />
      </inertial>

    </link>
    <link name="${prefix}link_4">
      <visual>
        <origin xyz="0 0 0" rpy="0 0 0"/>
        <geometry>
          <mesh filename="package://fanuc_r2000ic_support/meshes/r2000ic165f/visual/link_4.stl"/>
        </geometry>
        <xacro:material_fanuc_yellow />
      </visual>
      <collision>
        <origin xyz="0 0 0" rpy="0 0 0"/>
        <geometry>
          <mesh filename="package://fanuc_r2000ic_support/meshes/r2000ic165f/collision/link_4.stl"/>
        </geometry>
      </collision>
      <inertial>
               <mass value="5.0" />
               <origin rpy="0 0 0" xyz="0.711733 -0.002537 -0.000643" />
               <inertia ixx="0.000333" ixy="0.000044" ixz="0.000006" iyy="0.004287" iyz="-0.000000" izz="0.004282" />
      </inertial>

    </link>
    <link name="${prefix}link_5">
      <visual>
        <origin xyz="0 0 0" rpy="0 0 0"/>
        <geometry>
          <mesh filename="package://fanuc_r2000ic_support/meshes/r2000ic165f/visual/link_5.stl"/>
        </geometry>
        <xacro:material_fanuc_yellow />
      </visual>
      <collision>
        <origin xyz="0 0 0" rpy="0 0 0"/>
        <geometry>
          <mesh filename="package://fanuc_r2000ic_support/meshes/r2000ic165f/collision/link_5.stl"/>
        </geometry>
      </collision>
      <inertial>
                <mass value="8.0" />
                <origin rpy="0 0 0" xyz="0.042035 -0.024095 -0.001620" />
                <inertia ixx="0.000088" ixy="-0.000012" ixz="0.000000" iyy="0.000094" iyz="0.000000" izz="0.000118" />
      </inertial>

    </link>
    <link name="${prefix}link_6">
      <visual>
        <origin xyz="0 0 0" rpy="0 0 0"/>
        <geometry>
          <mesh filename="package://fanuc_r2000ic_support/meshes/r2000ic165f/visual/link_6.stl"/>
        </geometry>
        <xacro:material_fanuc_black />
      </visual>
      <collision>
        <origin xyz="0 0 0" rpy="0 0 0"/>
        <geometry>
          <mesh filename="package://fanuc_r2000ic_support/meshes/r2000ic165f/collision/link_6.stl"/>
        </geometry>
      </collision>
      <inertial>
                <mass value="5.0" />
                <origin rpy="0 0 0" xyz="-0.018677 -0.000000 -0.000002" />
                <inertia ixx="0.000002" ixy="0.000000" ixz="-0.000000" iyy="0.000001" iyz="0.000000" izz="0.000001" />
      </inertial>

    </link>
    <link name="${prefix}ef">
          <visual>
            <origin xyz="0 0 0" rpy="0 0 0"/>
            <geometry>
              <mesh filename="package://fanuc_r2000ic_support/meshes/r2000ic165f/visual/ef.stl"/>
            </geometry>
            <xacro:material_fanuc_yellow />
          </visual>
          <collision>
            <origin xyz="0 0 0" rpy="0 0 0"/>
            <geometry>
              <mesh filename="package://fanuc_r2000ic_support/meshes/r2000ic165f/collision/ef.stl"/>
            </geometry>
          </collision>
          <inertial>
                       <mass value="3.0" />
                       <origin rpy="0 0 0" xyz="0.0 0.0 0.0" />
                       <inertia ixx="0.000127" ixy="0.000000" ixz="0.000052" iyy="0.000194" iyz="0.000003" izz="0.000141" />
           </inertial>
        </link>


    <!-- joints: main serial chain -->
    <joint name="${prefix}joint_1" type="revolute">
      <origin xyz="0 0 0" rpy="0 0 0"/>
      <parent link="${prefix}base_link"/>
      <child link="${prefix}link_1"/>
      <axis xyz="0 0 1"/>
      <limit lower="${radians(-185)}" upper="${radians(185)}" effort="0" velocity="${radians(130)}"/>
    </joint>
    <joint name="${prefix}joint_2" type="revolute">
      <origin xyz="0.312 0 0.670" rpy="0 0 0"/>
      <parent link="${prefix}link_1"/>
      <child link="${prefix}link_2"/>
      <axis xyz="0 1 0"/>
      <limit lower="${radians(-60)}" upper="${radians(76)}" effort="0" velocity="${radians(115)}"/>
    </joint>
    <joint name="${prefix}joint_3" type="revolute">
      <origin xyz="0 0 1.075" rpy="0 0 0"/>
      <parent link="${prefix}link_2"/>
      <child link="${prefix}link_3"/>
      <axis xyz="0 -1 0"/>
      <limit lower="${radians(-132)}" upper="${radians(180)}" effort="0" velocity="${radians(125)}"/>
    </joint>
    <joint name="${prefix}joint_4" type="revolute">
      <origin xyz="0 0 0.225" rpy="0 0 0"/>
      <parent link="${prefix}link_3"/>
      <child link="${prefix}link_4"/>
      <axis xyz="-1 0 0"/>
      <limit lower="${radians(-360)}" upper="${radians(360)}" effort="0" velocity="${radians(180)}"/>
    </joint>
    <joint name="${prefix}joint_5" type="revolute">
      <origin xyz="1.280 0 0" rpy="0 0 0"/>
      <parent link="${prefix}link_4"/>
      <child link="${prefix}link_5"/>
      <axis xyz="0 -1 0"/>
      <limit lower="${radians(-125)}" upper="${radians(125)}" effort="0" velocity="${radians(180)}"/>
    </joint>
    <joint name="${prefix}joint_6" type="revolute">
      <origin xyz="0.215 0 0" rpy="0 0 0"/>
      <parent link="${prefix}link_5"/>
      <child link="${prefix}link_6"/>
      <axis xyz="-1 0 0"/>
      <limit lower="${radians(-360)}" upper="${radians(360)}" effort="0" velocity="${radians(260)}"/>
    </joint>



<!--<link name="part_link">
  <visual>
    <origin xyz="0 0 0" rpy="0 0 0"/>
    <geometry>
      <mesh filename="package://fanuc_r2000ic_support/meshes/r2000ic165f/visual/sandpart.stl"/>
    </geometry>
    <material name="">
      <color rgba="0.9 0.7 0.4 1.0"/>
    </material>
  </visual>

</link>



  <joint name="world_part_link" type="fixed">
      <parent link="base_link" />
      <child link="part_link" />
      <origin rpy="0 0 0" xyz="1.4 -0.4 0.6" />
  </joint>-->

    <!-- ROS-Industrial 'base' frame: base_link to Fanuc World Coordinates transform -->
    <link name="${prefix}base" />
    <joint name="${prefix}base_link-base" type="fixed">
      <origin xyz="0 0 0.670" rpy="0 0 0"/>
      <parent link="${prefix}base_link"/>
      <child link="${prefix}base"/>
    </joint>

    <!-- ROS-Industrial 'flange' frame: attachment point for EEF models -->
    <link name="${prefix}flange" />
    <joint name="${prefix}joint_6-flange" type="fixed">
      <origin xyz="0 0 0" rpy="0 0 0" />
      <parent link="${prefix}link_6" />
      <child link="${prefix}flange" />
    </joint>

    <!-- ROS-Industrial 'tool0' frame: all-zeros tool frame -->
    <link name="${prefix}tool0" />
    <joint name="${prefix}flange-tool0" type="fixed">
      <origin xyz="0 0 0" rpy="0 ${radians(90)} 0" />
      <parent link="${prefix}flange" />
      <child link="${prefix}tool0" />
    </joint>
    <joint name="${prefix}flange-ef" type="fixed">
          <origin xyz="0 0 0" rpy="${radians(180)} ${radians(-90)} 0" />
          <parent link="${prefix}tool0" />
          <child link="${prefix}ef" />
        </joint>

    <link name="${prefix}gazebo_camera_link" />
    <joint name="${prefix}gazebo_camera_joint" type="fixed">
        <origin xyz="0.0 0.0 0.0" rpy="1.57 -1.57 0.0"/>
        <parent link="${prefix}camera_link_optical"/>
        <child link="${prefix}gazebo_camera_link"/>
    </joint>
    <link name="${prefix}camera_link_optical" />
    <joint name="${prefix}camera_optical_joint" type="fixed">
        <origin xyz="-0.021 0.0797 0.06525" rpy="-0.7854 0 0"/>
        <parent link="${prefix}ef"/>
        <child link="${prefix}camera_link_optical"/>
    </joint>
    <link name="${prefix}camera_link" />
    <joint name="${prefix}camera_link_joint" type="fixed">
        <origin xyz="0.0 0.0 0.0" rpy="1.57 -1.57 0"/>
        <parent link="${prefix}camera_link_optical"/>
        <child link="${prefix}camera_link"/>
    </joint>

    <transmission name="joint_1">
        <type>transmission_interface/SimpleTransmission</type>
        <joint name="${prefix}joint_1">
            <hardwareInterface>hardware_interface/EffortJointInterface</hardwareInterface>
        </joint>
        <actuator name="joint_1_motor">
            <hardwareInterface>hardware_interface/EffortJointInterface</hardwareInterface>
            <mechanicalReduction>1</mechanicalReduction>
        </actuator>
    </transmission>

<transmission name="joint_2">
    <type>transmission_interface/SimpleTransmission</type>
    <joint name="${prefix}joint_2">
        <hardwareInterface>hardware_interface/EffortJointInterface</hardwareInterface>
    </joint>
    <actuator name="joint_2_motor">
        <hardwareInterface>hardware_interface/EffortJointInterface</hardwareInterface>
        <mechanicalReduction>1</mechanicalReduction>
    </actuator>
</transmission>

<transmission name="joint_3">
    <type>transmission_interface/SimpleTransmission</type>
    <joint name="${prefix}joint_3">
        <hardwareInterface>hardware_interface/EffortJointInterface</hardwareInterface>
    </joint>
    <actuator name="joint_3_motor">
        <hardwareInterface>hardware_interface/EffortJointInterface</hardwareInterface>
        <mechanicalReduction>1</mechanicalReduction>
    </actuator>
</transmission>

<transmission name="joint_4">
    <type>transmission_interface/SimpleTransmission</type>
    <joint name="${prefix}joint_4">
        <hardwareInterface>hardware_interface/EffortJointInterface</hardwareInterface>
    </joint>
    <actuator name="joint_4_motor">
        <hardwareInterface>hardware_interface/EffortJointInterface</hardwareInterface>
        <mechanicalReduction>1</mechanicalReduction>
    </actuator>
</transmission>

<transmission name="joint_5">
    <type>transmission_interface/SimpleTransmission</type>
    <joint name="${prefix}joint_5">
        <hardwareInterface>hardware_interface/EffortJointInterface</hardwareInterface>
    </joint>
    <actuator name="joint_5_motor">
        <hardwareInterface>hardware_interface/EffortJointInterface</hardwareInterface>
        <mechanicalReduction>1</mechanicalReduction>
    </actuator>
</transmission>

<transmission name="joint_6">
    <type>transmission_interface/SimpleTransmission</type>
    <joint name="${prefix}joint_6">
        <hardwareInterface>hardware_interface/EffortJointInterface</hardwareInterface>
    </joint>
    <actuator name="joint_6_motor">
        <hardwareInterface>hardware_interface/EffortJointInterface</hardwareInterface>
        <mechanicalReduction>1</mechanicalReduction>
    </actuator>
</transmission>



    <gazebo reference="${prefix}base_link">
        <selfCollide>true</selfCollide>
    </gazebo>
    <gazebo reference="${prefix}link_1">
        <selfCollide>true</selfCollide>
    </gazebo>
    <gazebo reference="${prefix}link_2">
        <selfCollide>true</selfCollide>
    </gazebo>
    <gazebo reference="${prefix}link_3">
        <selfCollide>true</selfCollide>
    </gazebo>
    <gazebo reference="${prefix}link_4">
        <selfCollide>true</selfCollide>
    </gazebo>
    <gazebo reference="${prefix}link_5">
        <selfCollide>true</selfCollide>
    </gazebo>
    <gazebo reference="${prefix}link_6">
        <selfCollide>true</selfCollide>
    </gazebo>
    <gazebo reference="${prefix}ef">
        <selfCollide>true</selfCollide>
    </gazebo>
    <gazebo reference="${prefix}joint_1">
        <selfCollide>true</selfCollide>
    </gazebo>
    <gazebo reference="${prefix}joint_2">
        <selfCollide>true</selfCollide>
    </gazebo>
    <gazebo reference="${prefix}joint_3">
        <selfCollide>true</selfCollide>
    </gazebo>
    <gazebo reference="${prefix}joint_4">
        <selfCollide>true</selfCollide>
    </gazebo>
    <gazebo reference="${prefix}joint_5">
        <selfCollide>true</selfCollide>
    </gazebo>
    <gazebo reference="${prefix}joint_6">
        <selfCollide>true</selfCollide>
    </gazebo>
    <gazebo reference="${prefix}flange-ef">
        <selfCollide>true</selfCollide>
    </gazebo>
    <gazebo reference="${prefix}tool0">
        <selfCollide>true</selfCollide>
    </gazebo>

    <gazebo reference="${prefix}base">
        <selfCollide>true</selfCollide>
    </gazebo>
    <gazebo reference="${prefix}flange">
        <selfCollide>true</selfCollide>
    </gazebo>
    <gazebo reference="tool0">
        <selfCollide>true</selfCollide>
    </gazebo>

<gazebo reference="gazebo_camera_link">
        <sensor type="depth" name="sensor_name">
          <!-- Set always_on only sensor, not on plugin -->
          <always_on>1</always_on>
          <!-- Set update_rate only sensor, not on plugin -->
          <update_rate>5</update_rate>
          <camera name="camera_name">
            <image>
              <width>320</width>
              <height>200</height>
            </image>
            <distortion>
              <k1>-0.0</k1>
              <k2>0.0</k2>
              <k3>0.0</k3>
              <p1>-0.0</p1>
              <p2>-0.0</p2>
              <center>0.5 0.5</center>
            </distortion>
          </camera>
          <plugin name="plugin_name" filename="libgazebo_ros_camera.so">
            <!-- Change namespace, camera name and topics so:
                 * Raw images are published to: /custom_ns/custom_camera/custom_image
                 * Depth images are published to: /custom_ns/custom_camera/custom_image_depth
                 * Raw image camera info is published to: /custom_ns/custom_camera/custom_info_raw
                 * Depth image camera info is published to: /custom_ns/custom_camera/custom_info_depth
                 * Point cloud is published to: /custom_ns/custom_camera/custom_points
            -->
            <ros>
              <namespace>custom_ns</namespace>
              <argument>camera/image_raw:=camera/custom_image</argument>
              <argument>camera/image_depth:=camera/custom_image_depth</argument>
              <argument>camera/camera_info:=camera/custom_info_raw</argument>
              <argument>camera/camera_info_depth:=camera/custom_info_depth</argument>
              <argument>camera/points:=camera/pointcloud</argument>
            </ros>
            <!-- Set camera name. If empty, defaults to sensor name (i.e. "sensor_name") -->
            <camera_name>camera</camera_name>
            <frame_name>camera_link_optical</frame_name>
            <!-- Set TF frame name. If empty, defaults to link name (i.e. "link_name") -->
            <hack_baseline>0.07</hack_baseline>
            <!-- No need to repeat distortion parameters or to set autoDistortion -->
             <min_depth>0.1</min_depth>
          </plugin>
        </sensor>
    </gazebo>

    <gazebo>
        <plugin name='gazebo_ros_joint_state_publisher' filename='libgazebo_ros_joint_state_publisher.so'>
          <ros>
              <namespace>/test</namespace>
              <argument>joint_states:=joint_states</argument>
          </ros>
          <update_rate>50</update_rate>

          <joint_name>${prefix}joint_1</joint_name>
          <joint_name>${prefix}joint_2</joint_name>
          <joint_name>${prefix}joint_3</joint_name>
          <joint_name>${prefix}joint_4</joint_name>
          <joint_name>${prefix}joint_5</joint_name>
          <joint_name>${prefix}joint_6</joint_name>


        </plugin>
        <plugin name='crs_gazebo_plugins_joint_pose_trajectory' filename='libcrs_gazebo_plugins_joint_pose_trajectory.so'>
            <ros>
              <namespace>sim</namespace>
              <argument>follow_joint_trajectory:=${prefix}follow_joint_trajectory</argument>
            </ros>
            <update_rate>20</update_rate>
        </plugin>
    </gazebo>


  </xacro:macro>
</robot>
